Workbook

Sheet PoD Calc
K2: manual model inputs | L2: Domino model outputs
K6: prompt | L6: response from =Domino.Agent.Narrate() | Q6: response from =Domino.Agent.ResearchAnalyst() | W6: prompt | X6: response from =Domino.Agent.Narrate() | AE6: response from =Domino.Agent.ResearchAnalyst() | AL6: prompt | AM6: response from =Domino.Agent.Analyze() | AO6: response from =Domino.Agent.ResearchAnalyst() | AS6: prompt | AT6: response from =Domino.Agent.Analyze() | AV6: response from =Domino.Agent.ResearchAnalyst()
K7: Describe this data and any anomolies that may stand out. | L7: {=_xll.Domino.Agent.Narrate(K7, K13:U41)} -> The discount factors for different tenors are generally decreasing as tenor increases, with some minor fluctuations around 0.8 for longer tenors. The risk-free rates show a slight upward trend from 0.035% to 0.0455%. The AAA spreads are consistently low, indicating minimal credit risk, while the BB and B spreads increase significantly with longer tenors. | Q7: {=_xll.Domino.Agent.ResearchAnalyst(K7, K13:U41)} -> Stable credit environment with low default risk; minor short-term rate decline; increasing credit risk with longer maturities; AAA spreads consistently lower; overall credit spreads trend upward. | W7: Describe this data and any anomolies that stand out. | X7: {=_xll.Domino.Agent.Narrate(W7,W13:AJ53)} -> The data shows loans with various characteristics such as loan purposes, credit scores, debt-to-income ratios, loan-to-value ratios, and delinquencies. Loan ID L001 has a high debt-to-income ratio (0.31) and a low credit score (667), while L036 has an exceptionally high delinquency rate at 93%. | AE7: {=_xll.Domino.Agent.ResearchAnalyst(W7,W13:AJ53)} -> Loan ID L006 and L036 highlight key risks; shorter term loans near maturity also pose significant default risks requiring proactive management. | AL7: Analyze potential risks and anomolies in this data. | AM7: {=_xll.Domino.Agent.Analyze(AL7,AL13:AQ53)} -> Highly concentrated probabilities near 1 indicating significant risk, especially for shorter maturities. | AO7: {=_xll.Domino.Agent.ResearchAnalyst(AL7,AL13:AQ53)} -> Probability of default increases significantly over time, especially near maturity, with high variability across sectors, highlighting the importance of close risk management. | AS7: Highlight hidden correlations in this data. | AT7: {=_xll.Domino.Agent.Analyze(AS7,AS13:AW53)} -> Hidden correlation: BB-rated entities have a higher expected loss (undiscounted) compared to other ratings, suggesting they carry greater risk. | AV7: ––
K10: UDF 0 - Get credit curves for current and historic dates | W10: UDF 1 - Get loan inventory for current date | AL10: UDF 2 - Calculate probability of default for each loan | AS10: UDF 3 - Calculate expected loss for each loan
K11: =_xlfn.FORMULATEXT(L14) -> =Domino.MLModel.GetCreditCurves(K14) | W11: =_xlfn.FORMULATEXT(X14) -> =Domino.MLModel.GetLoanInventory(W14, 40) | AL11: =_xlfn.FORMULATEXT(AL14) -> =Domino.MLModel.GetLoanProbabilityOfDefault($Z14,$AA14,$AB14,$AC14,$AD14,$AF14,$AG14,$AH14,$Y14,1) | AS11: =_xlfn.FORMULATEXT(AS14) -> =Domino.MLModel.GetExpectedLoss(AL14,AQ14,AB14,AE14,AJ14,$M$14:$M$20,$O$14:$O$20)
K13: curve date | L13: tenor | M13: tenor (years) | N13: discount factor | O13: risk free rate | P13: AAA spread | Q13: AA spread | R13: A spread | S13: BBB spread | T13: BB spread | U13: B spread | W13: inventory date | X13: loan id | Y13: loan purpose | Z13: credit score | AA13: debt to income ratio | AB13: loan to value ratio | AC13: loan age (months) | AD13: original principle | AE13: outstanding balance | AF13: interest rate | AG13: employment length (years) | AH13: delinquency 30d past 12m | AI13: original loan term (years) | AJ13: remaining term (years) | AL13: probability of default at 1 year | AM13: probability of default at 2 years | AN13: probability of default at 5 years | AO13: probability of default at 10 years | AP13: probability of default at 30 years | AQ13: probability of default at maturity | AS13: implied credit rating | AT13: implied loss given default | AU13: expected loss undiscounted | AV13: expected loss discounted | AW13: risk- weighted assets
K14: 45293 | L14: {=_xll.Domino.MLModel.GetCreditCurves(K14)} -> 3M | M14: 0.25 | N14: 0.990669 | O14: 0.0375 | P14: 0.004375 | Q14: 0.0091 | R14: 0.01275 | S14: 0.019125 | T14: 0.035 | U14: 0.05605 | W14: =K14 -> 45293 | X14: {=_xll.Domino.MLModel.GetLoanInventory(W14, 40)} -> L001 | Y14: purchase | Z14: 667 | AA14: 0.31 | AB14: 0.83 | AC14: 49 | AD14: 320000 | AE14: 302660.57 | AF14: 0.061 | AG14: 3 | AH14: 0 | AI14: 30 | AJ14: 25 | AL14: {=_xll.Domino.MLModel.GetLoanProbabilityOfDefault($Z14,$AA14,$AB14,$AC14,$AD14,$AF14,$AG14,$AH14,$Y14,1)} -> 0.012525201 | AM14: {=_xll.Domino.MLModel.GetLoanProbabilityOfDefault($Z14,$AA14,$AB14,$AC14,$AD14,$AF14,$AG14,$AH14,$Y14,2)} -> 0.024893521 | AN14: {=_xll.Domino.MLModel.GetLoanProbabilityOfDefault($Z14,$AA14,$AB14,$AC14,$AD14,$AF14,$AG14,$AH14,$Y14,5)} -> 0.061076725 | AO14: {=_xll.Domino.MLModel.GetLoanProbabilityOfDefault($Z14,$AA14,$AB14,$AC14,$AD14,$AF14,$AG14,$AH14,$Y14,10)} -> 0.11842308 | AP14: {=_xll.Domino.MLModel.GetLoanProbabilityOfDefault($Z14,$AA14,$AB14,$AC14,$AD14,$AF14,$AG14,$AH14,$Y14,30)} -> 0.31485794 | AQ14: {=_xll.Domino.MLModel.GetLoanProbabilityOfDefault($Z14,$AA14,$AB14,$AC14,$AD14,$AF14,$AG14,$AH14,$Y14,AJ14)} -> 0.27028962 | AS14: {=_xll.Domino.MLModel.GetExpectedLoss(AL14,AQ14,AB14,AE14,AJ14,$M$14:$M$20,$O$14:$O$20)} -> BB | AT14: 0.23 | AU14: 18815.382 | AV14: 1177.5367 | AW14: 151330.29
L15: 1Y | M15: 1 | N15: 0.96493 | O15: 0.0357 | P15: 0.0046 | Q15: 0.0094 | R15: 0.0132 | S15: 0.0198 | T15: 0.0359 | U15: 0.0574 | X15: L002 | Y15: purchase | Z15: 661 | AA15: 0.35 | AB15: 0.79 | AC15: 39 | AD15: 500000 | AE15: 456766.92 | AF15: 0.067 | AG15: 9 | AH15: 0 | AI15: 20 | AJ15: 16 | AL15: {=_xll.Domino.MLModel.GetLoanProbabilityOfDefault($Z15,$AA15,$AB15,$AC15,$AD15,$AF15,$AG15,$AH15,$Y15,1)} -> 0.0020979047 | AM15: {=_xll.Domino.MLModel.GetLoanProbabilityOfDefault($Z15,$AA15,$AB15,$AC15,$AD15,$AF15,$AG15,$AH15,$Y15,2)} -> 0.0041914082 | AN15: {=_xll.Domino.MLModel.GetLoanProbabilityOfDefault($Z15,$AA15,$AB15,$AC15,$AD15,$AF15,$AG15,$AH15,$Y15,5)} -> 0.010445604 | AO15: {=_xll.Domino.MLModel.GetLoanProbabilityOfDefault($Z15,$AA15,$AB15,$AC15,$AD15,$AF15,$AG15,$AH15,$Y15,10)} -> 0.020782097 | AP15: {=_xll.Domino.MLModel.GetLoanProbabilityOfDefault($Z15,$AA15,$AB15,$AC15,$AD15,$AF15,$AG15,$AH15,$Y15,30)} -> 0.061059579 | AQ15: {=_xll.Domino.MLModel.GetLoanProbabilityOfDefault($Z15,$AA15,$AB15,$AC15,$AD15,$AF15,$AG15,$AH15,$Y15,AJ15)} -> 0.033043466 | AS15: {=_xll.Domino.MLModel.GetExpectedLoss(AL15,AQ15,AB15,AE15,AJ15,$M$14:$M$20,$O$14:$O$20)} -> BBB | AT15: 0.19 | AU15: 2867.7008 | AV15: 858.49931 | AW15: 159868.42
L16: 2Y | M16: 2 | N16: 0.931089 | O16: 0.0357 | P16: 0.0049 | Q16: 0.0098 | R16: 0.0138 | S16: 0.0207 | T16: 0.0371 | U16: 0.0592 | X16: L003 | Y16: purchase | Z16: 682 | AA16: 0.4 | AB16: 0.85 | AC16: 51 | AD16: 420000 | AE16: 392313.37 | AF16: 0.052 | AG16: 2 | AH16: 0 | AI16: 30 | AJ16: 25 | AL16: {=_xll.Domino.MLModel.GetLoanProbabilityOfDefault($Z16,$AA16,$AB16,$AC16,$AD16,$AF16,$AG16,$AH16,$Y16,1)} -> 0.023311079 | AM16: {=_xll.Domino.MLModel.GetLoanProbabilityOfDefault($Z16,$AA16,$AB16,$AC16,$AD16,$AF16,$AG16,$AH16,$Y16,2)} -> 0.046078751 | AN16: {=_xll.Domino.MLModel.GetLoanProbabilityOfDefault($Z16,$AA16,$AB16,$AC16,$AD16,$AF16,$AG16,$AH16,$Y16,5)} -> 0.11124653 | AO16: {=_xll.Domino.MLModel.GetLoanProbabilityOfDefault($Z16,$AA16,$AB16,$AC16,$AD16,$AF16,$AG16,$AH16,$Y16,10)} -> 0.21011728 | AP16: {=_xll.Domino.MLModel.GetLoanProbabilityOfDefault($Z16,$AA16,$AB16,$AC16,$AD16,$AF16,$AG16,$AH16,$Y16,30)} -> 0.50718054 | AQ16: {=_xll.Domino.MLModel.GetLoanProbabilityOfDefault($Z16,$AA16,$AB16,$AC16,$AD16,$AF16,$AG16,$AH16,$Y16,AJ16)} -> 0.44549363 | AS16: {=_xll.Domino.MLModel.GetExpectedLoss(AL16,AQ16,AB16,AE16,AJ16,$M$14:$M$20,$O$14:$O$20)} -> B | AT16: 0.25 | AU16: 43693.277 | AV16: 1162.9318 | AW16: 196156.68
L17: 3Y | M17: 3 | N17: 0.896282 | O17: 0.0365 | P17: 0.0052 | Q17: 0.0102 | R17: 0.0144 | S17: 0.0216 | T17: 0.0383 | U17: 0.061 | X17: L004 | Y17: purchase | Z17: 712 | AA17: 0.42 | AB17: 0.8 | AC17: 52 | AD17: 315000 | AE17: 296742.27 | AF17: 0.061 | AG17: 7 | AH17: 0 | AI17: 30 | AJ17: 25 | AL17: {=_xll.Domino.MLModel.GetLoanProbabilityOfDefault($Z17,$AA17,$AB17,$AC17,$AD17,$AF17,$AG17,$AH17,$Y17,1)} -> 0.011562347 | AM17: {=_xll.Domino.MLModel.GetLoanProbabilityOfDefault($Z17,$AA17,$AB17,$AC17,$AD17,$AF17,$AG17,$AH17,$Y17,2)} -> 0.022991007 | AN17: {=_xll.Domino.MLModel.GetLoanProbabilityOfDefault($Z17,$AA17,$AB17,$AC17,$AD17,$AF17,$AG17,$AH17,$Y17,5)} -> 0.056490227 | AO17: {=_xll.Domino.MLModel.GetLoanProbabilityOfDefault($Z17,$AA17,$AB17,$AC17,$AD17,$AF17,$AG17,$AH17,$Y17,10)} -> 0.10978931 | AP17: {=_xll.Domino.MLModel.GetLoanProbabilityOfDefault($Z17,$AA17,$AB17,$AC17,$AD17,$AF17,$AG17,$AH17,$Y17,30)} -> 0.29453021 | AQ17: {=_xll.Domino.MLModel.GetLoanProbabilityOfDefault($Z17,$AA17,$AB17,$AC17,$AD17,$AF17,$AG17,$AH17,$Y17,AJ17)} -> 0.25229202 | AS17: {=_xll.Domino.MLModel.GetExpectedLoss(AL17,AQ17,AB17,AE17,AJ17,$M$14:$M$20,$O$14:$O$20)} -> BB | AT17: 0.2 | AU17: 14973.141 | AV17: 937.07498 | AW17: 103859.79
L18: 5Y | M18: 5 | N18: 0.825307 | O18: 0.0384 | P18: 0.0058 | Q18: 0.011 | R18: 0.0156 | S18: 0.0234 | T18: 0.0407 | U18: 0.0646 | X18: L005 | Y18: purchase | Z18: 733 | AA18: 0.32 | AB18: 0.74 | AC18: 70 | AD18: 335000 | AE18: 305760.12 | AF18: 0.057 | AG18: 2 | AH18: 0 | AI18: 30 | AJ18: 24 | AL18: {=_xll.Domino.MLModel.GetLoanProbabilityOfDefault($Z18,$AA18,$AB18,$AC18,$AD18,$AF18,$AG18,$AH18,$Y18,1)} -> 0.0058357716 | AM18: {=_xll.Domino.MLModel.GetLoanProbabilityOfDefault($Z18,$AA18,$AB18,$AC18,$AD18,$AF18,$AG18,$AH18,$Y18,2)} -> 0.011637487 | AN18: {=_xll.Domino.MLModel.GetLoanProbabilityOfDefault($Z18,$AA18,$AB18,$AC18,$AD18,$AF18,$AG18,$AH18,$Y18,5)} -> 0.028840277 | AO18: {=_xll.Domino.MLModel.GetLoanProbabilityOfDefault($Z18,$AA18,$AB18,$AC18,$AD18,$AF18,$AG18,$AH18,$Y18,10)} -> 0.056848793 | AP18: {=_xll.Domino.MLModel.GetLoanProbabilityOfDefault($Z18,$AA18,$AB18,$AC18,$AD18,$AF18,$AG18,$AH18,$Y18,30)} -> 0.16103475 | AQ18: {=_xll.Domino.MLModel.GetLoanProbabilityOfDefault($Z18,$AA18,$AB18,$AC18,$AD18,$AF18,$AG18,$AH18,$Y18,AJ18)} -> 0.13104921 | AS18: {=_xll.Domino.MLModel.GetExpectedLoss(AL18,AQ18,AB18,AE18,AJ18,$M$14:$M$20,$O$14:$O$20)} -> BB | AT18: 0.14 | AU18: 5609.7473 | AV18: 404.95703 | AW18: 107016.04
L19: 10Y | M19: 10 | N19: 0.65116 | O19: 0.0429 | P19: 0.0073 | Q19: 0.013 | R19: 0.0186 | S19: 0.0279 | T19: 0.0467 | U19: 0.0736 | X19: L006 | Y19: refi | Z19: 727 | AA19: 0.25 | AB19: 0.93 | AC19: 51 | AD19: 230000 | AE19: 216509.83 | AF19: 0.059 | AG19: 8 | AH19: 0 | AI19: 30 | AJ19: 25 | AL19: {=_xll.Domino.MLModel.GetLoanProbabilityOfDefault($Z19,$AA19,$AB19,$AC19,$AD19,$AF19,$AG19,$AH19,$Y19,1)} -> 0.00917238 | AM19: {=_xll.Domino.MLModel.GetLoanProbabilityOfDefault($Z19,$AA19,$AB19,$AC19,$AD19,$AF19,$AG19,$AH19,$Y19,2)} -> 0.018260627 | AN19: {=_xll.Domino.MLModel.GetLoanProbabilityOfDefault($Z19,$AA19,$AB19,$AC19,$AD19,$AF19,$AG19,$AH19,$Y19,5)} -> 0.045028256 | AO19: {=_xll.Domino.MLModel.GetLoanProbabilityOfDefault($Z19,$AA19,$AB19,$AC19,$AD19,$AF19,$AG19,$AH19,$Y19,10)} -> 0.088028968 | AP19: {=_xll.Domino.MLModel.GetLoanProbabilityOfDefault($Z19,$AA19,$AB19,$AC19,$AD19,$AF19,$AG19,$AH19,$Y19,30)} -> 0.24152175 | AQ19: {=_xll.Domino.MLModel.GetLoanProbabilityOfDefault($Z19,$AA19,$AB19,$AC19,$AD19,$AF19,$AG19,$AH19,$Y19,AJ19)} -> 0.20575844 | AS19: {=_xll.Domino.MLModel.GetExpectedLoss(AL19,AQ19,AB19,AE19,AJ19,$M$14:$M$20,$O$14:$O$20)} -> BB | AT19: 0.33 | AU19: 14701.079 | AV19: 920.04831 | AW19: 162382.37
L20: 30Y | M20: 30 | N20: 0.255381 | O20: 0.0455 | P20: 0.0133 | Q20: 0.021 | R20: 0.0306 | S20: 0.0459 | T20: 0.0707 | U20: 0.1096 | X20: L007 | Y20: purchase | Z20: 675 | AA20: 0.42 | AB20: 0.88 | AC20: 69 | AD20: 225000 | AE20: 202069.04 | AF20: 0.046 | AG20: 5 | AH20: 0 | AI20: 30 | AJ20: 24 | AL20: {=_xll.Domino.MLModel.GetLoanProbabilityOfDefault($Z20,$AA20,$AB20,$AC20,$AD20,$AF20,$AG20,$AH20,$Y20,1)} -> 0.018420935 | AM20: {=_xll.Domino.MLModel.GetLoanProbabilityOfDefault($Z20,$AA20,$AB20,$AC20,$AD20,$AF20,$AG20,$AH20,$Y20,2)} -> 0.036502539 | AN20: {=_xll.Domino.MLModel.GetLoanProbabilityOfDefault($Z20,$AA20,$AB20,$AC20,$AD20,$AF20,$AG20,$AH20,$Y20,5)} -> 0.088773299 | AO20: {=_xll.Domino.MLModel.GetLoanProbabilityOfDefault($Z20,$AA20,$AB20,$AC20,$AD20,$AF20,$AG20,$AH20,$Y20,10)} -> 0.1696659 | AP20: {=_xll.Domino.MLModel.GetLoanProbabilityOfDefault($Z20,$AA20,$AB20,$AC20,$AD20,$AF20,$AG20,$AH20,$Y20,30)} -> 0.42752224 | AQ20: {=_xll.Domino.MLModel.GetLoanProbabilityOfDefault($Z20,$AA20,$AB20,$AC20,$AD20,$AF20,$AG20,$AH20,$Y20,AJ20)} -> 0.35996032 | AS20: {=_xll.Domino.MLModel.GetExpectedLoss(AL20,AQ20,AB20,AE20,AJ20,$M$14:$M$20,$O$14:$O$20)} -> BB | AT20: 0.28 | AU20: 20366.314 | AV20: 1470.2056 | AW20: 101034.52
K21: =DATE(YEAR(K14),MONTH(K14)-1,DAY(K14)) -> 45262 | L21: {=_xll.Domino.MLModel.GetCreditCurves(K21)} -> 3M | M21: 0.25 | N21: 0.99104 | O21: 0.036 | P21: 0.005875 | Q21: 0.0088 | R21: 0.01235 | S21: 0.017225 | T21: 0.0356 | U21: 0.05455 | X21: L008 | Y21: purchase | Z21: 755 | AA21: 0.31 | AB21: 0.75 | AC21: 64 | AD21: 120000 | AE21: 102848.91 | AF21: 0.074 | AG21: 1 | AH21: 0 | AI21: 20 | AJ21: 14 | AL21: {=_xll.Domino.MLModel.GetLoanProbabilityOfDefault($Z21,$AA21,$AB21,$AC21,$AD21,$AF21,$AG21,$AH21,$Y21,1)} -> 0.0068179965 | AM21: {=_xll.Domino.MLModel.GetLoanProbabilityOfDefault($Z21,$AA21,$AB21,$AC21,$AD21,$AF21,$AG21,$AH21,$Y21,2)} -> 0.013589508 | AN21: {=_xll.Domino.MLModel.GetLoanProbabilityOfDefault($Z21,$AA21,$AB21,$AC21,$AD21,$AF21,$AG21,$AH21,$Y21,5)} -> 0.03362829 | AO21: {=_xll.Domino.MLModel.GetLoanProbabilityOfDefault($Z21,$AA21,$AB21,$AC21,$AD21,$AF21,$AG21,$AH21,$Y21,10)} -> 0.066125719 | AP21: {=_xll.Domino.MLModel.GetLoanProbabilityOfDefault($Z21,$AA21,$AB21,$AC21,$AD21,$AF21,$AG21,$AH21,$Y21,30)} -> 0.18554847 | AQ21: {=_xll.Domino.MLModel.GetLoanProbabilityOfDefault($Z21,$AA21,$AB21,$AC21,$AD21,$AF21,$AG21,$AH21,$Y21,AJ21)} -> 0.09133504 | AS21: {=_xll.Domino.MLModel.GetExpectedLoss(AL21,AQ21,AB21,AE21,AJ21,$M$14:$M$20,$O$14:$O$20)} -> BB | AT21: 0.15 | AU21: 1409.0564 | AV21: 366.35233 | AW21: 35997.118
L22: 1Y | M22: 1 | N22: 0.966378 | O22: 0.0342 | P22: 0.0061 | Q22: 0.0091 | R22: 0.0128 | S22: 0.0179 | T22: 0.0365 | U22: 0.0559 | X22: L009 | Y22: refi | Z22: 739 | AA22: 0.38 | AB22: 0.87 | AC22: 14 | AD22: 320000 | AE22: 311460.75 | AF22: 0.043 | AG22: 7 | AH22: 0 | AI22: 25 | AJ22: 23 | AL22: {=_xll.Domino.MLModel.GetLoanProbabilityOfDefault($Z22,$AA22,$AB22,$AC22,$AD22,$AF22,$AG22,$AH22,$Y22,1)} -> 0.0040122271 | AM22: {=_xll.Domino.MLModel.GetLoanProbabilityOfDefault($Z22,$AA22,$AB22,$AC22,$AD22,$AF22,$AG22,$AH22,$Y22,2)} -> 0.0080083562 | AN22: {=_xll.Domino.MLModel.GetLoanProbabilityOfDefault($Z22,$AA22,$AB22,$AC22,$AD22,$AF22,$AG22,$AH22,$Y22,5)} -> 0.0199008 | AO22: {=_xll.Domino.MLModel.GetLoanProbabilityOfDefault($Z22,$AA22,$AB22,$AC22,$AD22,$AF22,$AG22,$AH22,$Y22,10)} -> 0.039405559 | AP22: {=_xll.Domino.MLModel.GetLoanProbabilityOfDefault($Z22,$AA22,$AB22,$AC22,$AD22,$AF22,$AG22,$AH22,$Y22,30)} -> 0.11361947 | AQ22: {=_xll.Domino.MLModel.GetLoanProbabilityOfDefault($Z22,$AA22,$AB22,$AC22,$AD22,$AF22,$AG22,$AH22,$Y22,AJ22)} -> 0.088320563 | AS22: {=_xll.Domino.MLModel.GetExpectedLoss(AL22,AQ22,AB22,AE22,AJ22,$M$14:$M$20,$O$14:$O$20)} -> BBB | AT22: 0.27 | AU22: 7427.265 | AV22: 1111.3636 | AW22: 155730.38
L23: 2Y | M23: 2 | N23: 0.933887 | O23: 0.0342 | P23: 0.0064 | Q23: 0.0095 | R23: 0.0134 | S23: 0.0188 | T23: 0.0377 | U23: 0.0577 | X23: L010 | Y23: purchase | Z23: 758 | AA23: 0.25 | AB23: 0.93 | AC23: 67 | AD23: 360000 | AE23: 294789.13 | AF23: 0.054 | AG23: 12 | AH23: 0 | AI23: 20 | AJ23: 14 | AL23: {=_xll.Domino.MLModel.GetLoanProbabilityOfDefault($Z23,$AA23,$AB23,$AC23,$AD23,$AF23,$AG23,$AH23,$Y23,1)} -> 0.01264447 | AM23: {=_xll.Domino.MLModel.GetLoanProbabilityOfDefault($Z23,$AA23,$AB23,$AC23,$AD23,$AF23,$AG23,$AH23,$Y23,2)} -> 0.025129057 | AN23: {=_xll.Domino.MLModel.GetLoanProbabilityOfDefault($Z23,$AA23,$AB23,$AC23,$AD23,$AF23,$AG23,$AH23,$Y23,5)} -> 0.061643611 | AO23: {=_xll.Domino.MLModel.GetLoanProbabilityOfDefault($Z23,$AA23,$AB23,$AC23,$AD23,$AF23,$AG23,$AH23,$Y23,10)} -> 0.11948729 | AP23: {=_xll.Domino.MLModel.GetLoanProbabilityOfDefault($Z23,$AA23,$AB23,$AC23,$AD23,$AF23,$AG23,$AH23,$Y23,30)} -> 0.31733617 | AQ23: {=_xll.Domino.MLModel.GetLoanProbabilityOfDefault($Z23,$AA23,$AB23,$AC23,$AD23,$AF23,$AG23,$AH23,$Y23,AJ23)} -> 0.16318418 | AS23: {=_xll.Domino.MLModel.GetExpectedLoss(AL23,AQ23,AB23,AE23,AJ23,$M$14:$M$20,$O$14:$O$20)} -> BB | AT23: 0.33 | AU23: 15874.624 | AV23: 4127.3761 | AW23: 221091.85
L24: 3Y | M24: 3 | N24: 0.900325 | O24: 0.035 | P24: 0.0067 | Q24: 0.0099 | R24: 0.014 | S24: 0.0197 | T24: 0.0389 | U24: 0.0595 | X24: L011 | Y24: purchase | Z24: 711 | AA24: 0.26 | AB24: 0.9 | AC24: 52 | AD24: 300000 | AE24: 280767.87 | AF24: 0.055 | AG24: 1 | AH24: 0 | AI24: 30 | AJ24: 25 | AL24: {=_xll.Domino.MLModel.GetLoanProbabilityOfDefault($Z24,$AA24,$AB24,$AC24,$AD24,$AF24,$AG24,$AH24,$Y24,1)} -> 0.0015601516 | AM24: {=_xll.Domino.MLModel.GetLoanProbabilityOfDefault($Z24,$AA24,$AB24,$AC24,$AD24,$AF24,$AG24,$AH24,$Y24,2)} -> 0.0031178691 | AN24: {=_xll.Domino.MLModel.GetLoanProbabilityOfDefault($Z24,$AA24,$AB24,$AC24,$AD24,$AF24,$AG24,$AH24,$Y24,5)} -> 0.0077764551 | AO24: {=_xll.Domino.MLModel.GetLoanProbabilityOfDefault($Z24,$AA24,$AB24,$AC24,$AD24,$AF24,$AG24,$AH24,$Y24,10)} -> 0.015492437 | AP24: {=_xll.Domino.MLModel.GetLoanProbabilityOfDefault($Z24,$AA24,$AB24,$AC24,$AD24,$AF24,$AG24,$AH24,$Y24,30)} -> 0.045760982 | AQ24: {=_xll.Domino.MLModel.GetLoanProbabilityOfDefault($Z24,$AA24,$AB24,$AC24,$AD24,$AF24,$AG24,$AH24,$Y24,AJ24)} -> 0.038282227 | AS24: {=_xll.Domino.MLModel.GetExpectedLoss(AL24,AQ24,AB24,AE24,AJ24,$M$14:$M$20,$O$14:$O$20)} -> A | AT24: 0.3 | AU24: 3224.5258 | AV24: 531.01549 | AW24: 140383.93
L25: 5Y | M25: 5 | N25: 0.83152 | O25: 0.0369 | P25: 0.0073 | Q25: 0.0107 | R25: 0.0152 | S25: 0.0215 | T25: 0.0413 | U25: 0.0631 | X25: L012 | Y25: refi | Z25: 679 | AA25: 0.24 | AB25: 0.85 | AC25: 13 | AD25: 220000 | AE25: 216898.12 | AF25: 0.057 | AG25: 5 | AH25: 0 | AI25: 30 | AJ25: 28 | AL25: {=_xll.Domino.MLModel.GetLoanProbabilityOfDefault($Z25,$AA25,$AB25,$AC25,$AD25,$AF25,$AG25,$AH25,$Y25,1)} -> 0.019431293 | AM25: {=_xll.Domino.MLModel.GetLoanProbabilityOfDefault($Z25,$AA25,$AB25,$AC25,$AD25,$AF25,$AG25,$AH25,$Y25,2)} -> 0.038485011 | AN25: {=_xll.Domino.MLModel.GetLoanProbabilityOfDefault($Z25,$AA25,$AB25,$AC25,$AD25,$AF25,$AG25,$AH25,$Y25,5)} -> 0.093453371 | AO25: {=_xll.Domino.MLModel.GetLoanProbabilityOfDefault($Z25,$AA25,$AB25,$AC25,$AD25,$AF25,$AG25,$AH25,$Y25,10)} -> 0.17817321 | AP25: {=_xll.Domino.MLModel.GetLoanProbabilityOfDefault($Z25,$AA25,$AB25,$AC25,$AD25,$AF25,$AG25,$AH25,$Y25,30)} -> 0.44493878 | AQ25: {=_xll.Domino.MLModel.GetLoanProbabilityOfDefault($Z25,$AA25,$AB25,$AC25,$AD25,$AF25,$AG25,$AH25,$Y25,AJ25)} -> 0.42272224 | AS25: {=_xll.Domino.MLModel.GetExpectedLoss(AL25,AQ25,AB25,AE25,AJ25,$M$14:$M$20,$O$14:$O$20)} -> BB | AT25: 0.25 | AU25: 22921.915 | AV25: 919.95864 | AW25: 108449.06
L26: 10Y | M26: 10 | N26: 0.661001 | O26: 0.0414 | P26: 0.0088 | Q26: 0.0127 | R26: 0.0182 | S26: 0.026 | T26: 0.0473 | U26: 0.0721 | X26: L013 | Y26: purchase | Z26: 690 | AA26: 0.25 | AB26: 0.89 | AC26: 13 | AD26: 400000 | AE26: 389966 | AF26: 0.042 | AG26: 10 | AH26: 0 | AI26: 25 | AJ26: 23 | AL26: {=_xll.Domino.MLModel.GetLoanProbabilityOfDefault($Z26,$AA26,$AB26,$AC26,$AD26,$AF26,$AG26,$AH26,$Y26,1)} -> 0.0029231906 | AM26: {=_xll.Domino.MLModel.GetLoanProbabilityOfDefault($Z26,$AA26,$AB26,$AC26,$AD26,$AF26,$AG26,$AH26,$Y26,2)} -> 0.0058378361 | AN26: {=_xll.Domino.MLModel.GetLoanProbabilityOfDefault($Z26,$AA26,$AB26,$AC26,$AD26,$AF26,$AG26,$AH26,$Y26,5)} -> 0.014530752 | AO26: {=_xll.Domino.MLModel.GetLoanProbabilityOfDefault($Z26,$AA26,$AB26,$AC26,$AD26,$AF26,$AG26,$AH26,$Y26,10)} -> 0.028850361 | AP26: {=_xll.Domino.MLModel.GetLoanProbabilityOfDefault($Z26,$AA26,$AB26,$AC26,$AD26,$AF26,$AG26,$AH26,$Y26,30)} -> 0.084078067 | AQ26: {=_xll.Domino.MLModel.GetLoanProbabilityOfDefault($Z26,$AA26,$AB26,$AC26,$AD26,$AF26,$AG26,$AH26,$Y26,AJ26)} -> 0.065115086 | AS26: {=_xll.Domino.MLModel.GetExpectedLoss(AL26,AQ26,AB26,AE26,AJ26,$M$14:$M$20,$O$14:$O$20)} -> BBB | AT26: 0.29 | AU26: 7363.8742 | AV26: 1101.8782 | AW26: 194983
L27: 30Y | M27: 30 | N27: 0.267135 | O27: 0.044 | P27: 0.0148 | Q27: 0.0207 | R27: 0.0302 | S27: 0.044 | T27: 0.0713 | U27: 0.1081 | X27: L014 | Y27: purchase | Z27: 684 | AA27: 0.28 | AB27: 0.9 | AC27: 88 | AD27: 320000 | AE27: 280994.21 | AF27: 0.053 | AG27: 1 | AH27: 0 | AI27: 30 | AJ27: 22 | AL27: {=_xll.Domino.MLModel.GetLoanProbabilityOfDefault($Z27,$AA27,$AB27,$AC27,$AD27,$AF27,$AG27,$AH27,$Y27,1)} -> 0.005136013 | AM27: {=_xll.Domino.MLModel.GetLoanProbabilityOfDefault($Z27,$AA27,$AB27,$AC27,$AD27,$AF27,$AG27,$AH27,$Y27,2)} -> 0.010245647 | AN27: {=_xll.Domino.MLModel.GetLoanProbabilityOfDefault($Z27,$AA27,$AB27,$AC27,$AD27,$AF27,$AG27,$AH27,$Y27,5)} -> 0.02541763 | AO27: {=_xll.Domino.MLModel.GetLoanProbabilityOfDefault($Z27,$AA27,$AB27,$AC27,$AD27,$AF27,$AG27,$AH27,$Y27,10)} -> 0.050189204 | AP27: {=_xll.Domino.MLModel.GetLoanProbabilityOfDefault($Z27,$AA27,$AB27,$AC27,$AD27,$AF27,$AG27,$AH27,$Y27,30)} -> 0.14313717 | AQ27: {=_xll.Domino.MLModel.GetLoanProbabilityOfDefault($Z27,$AA27,$AB27,$AC27,$AD27,$AF27,$AG27,$AH27,$Y27,AJ27)} -> 0.10710247 | AS27: {=_xll.Domino.MLModel.GetExpectedLoss(AL27,AQ27,AB27,AE27,AJ27,$M$14:$M$20,$O$14:$O$20)} -> BB | AT27: 0.3 | AU27: 9028.5519 | AV27: 860.25363 | AW27: 140497.11
K28: =DATE(YEAR(K21),MONTH(K21)-1,DAY(K21)) -> 45232 | L28: {=_xll.Domino.MLModel.GetCreditCurves(K28)} -> 3M | M28: 0.25 | N28: 0.991263 | O28: 0.0351 | P28: 0.004575 | Q28: 0.0084 | R28: 0.01295 | S28: 0.018125 | T28: 0.0347 | U28: 0.05585 | X28: L015 | Y28: purchase | Z28: 742 | AA28: 0.22 | AB28: 0.84 | AC28: 13 | AD28: 425000 | AE28: 416736.67 | AF28: 0.039 | AG28: 19 | AH28: 0 | AI28: 30 | AJ28: 28 | AL28: {=_xll.Domino.MLModel.GetLoanProbabilityOfDefault($Z28,$AA28,$AB28,$AC28,$AD28,$AF28,$AG28,$AH28,$Y28,1)} -> 0.0075451136 | AM28: {=_xll.Domino.MLModel.GetLoanProbabilityOfDefault($Z28,$AA28,$AB28,$AC28,$AD28,$AF28,$AG28,$AH28,$Y28,2)} -> 0.015033298 | AN28: {=_xll.Domino.MLModel.GetLoanProbabilityOfDefault($Z28,$AA28,$AB28,$AC28,$AD28,$AF28,$AG28,$AH28,$Y28,5)} -> 0.03716056 | AO28: {=_xll.Domino.MLModel.GetLoanProbabilityOfDefault($Z28,$AA28,$AB28,$AC28,$AD28,$AF28,$AG28,$AH28,$Y28,10)} -> 0.072940212 | AP28: {=_xll.Domino.MLModel.GetLoanProbabilityOfDefault($Z28,$AA28,$AB28,$AC28,$AD28,$AF28,$AG28,$AH28,$Y28,30)} -> 0.20324787 | AQ28: {=_xll.Domino.MLModel.GetLoanProbabilityOfDefault($Z28,$AA28,$AB28,$AC28,$AD28,$AF28,$AG28,$AH28,$Y28,AJ28)} -> 0.19108725 | AS28: {=_xll.Domino.MLModel.GetExpectedLoss(AL28,AQ28,AB28,AE28,AJ28,$M$14:$M$20,$O$14:$O$20)} -> BB | AT28: 0.24 | AU28: 19111.935 | AV28: 767.04717 | AW28: 208368.33
L29: 1Y | M29: 1 | N29: 0.967248 | O29: 0.0333 | P29: 0.0048 | Q29: 0.0087 | R29: 0.0134 | S29: 0.0188 | T29: 0.0356 | U29: 0.0572 | X29: L016 | Y29: refi | Z29: 778 | AA29: 0.29 | AB29: 0.72 | AC29: 84 | AD29: 315000 | AE29: 279233.39 | AF29: 0.054 | AG29: 7 | AH29: 0 | AI29: 30 | AJ29: 23 | AL29: {=_xll.Domino.MLModel.GetLoanProbabilityOfDefault($Z29,$AA29,$AB29,$AC29,$AD29,$AF29,$AG29,$AH29,$Y29,1)} -> 0.0015028119 | AM29: {=_xll.Domino.MLModel.GetLoanProbabilityOfDefault($Z29,$AA29,$AB29,$AC29,$AD29,$AF29,$AG29,$AH29,$Y29,2)} -> 0.0030033654 | AN29: {=_xll.Domino.MLModel.GetLoanProbabilityOfDefault($Z29,$AA29,$AB29,$AC29,$AD29,$AF29,$AG29,$AH29,$Y29,5)} -> 0.007491509 | AO29: {=_xll.Domino.MLModel.GetLoanProbabilityOfDefault($Z29,$AA29,$AB29,$AC29,$AD29,$AF29,$AG29,$AH29,$Y29,10)} -> 0.014926895 | AP29: {=_xll.Domino.MLModel.GetLoanProbabilityOfDefault($Z29,$AA29,$AB29,$AC29,$AD29,$AF29,$AG29,$AH29,$Y29,30)} -> 0.044115575 | AQ29: {=_xll.Domino.MLModel.GetLoanProbabilityOfDefault($Z29,$AA29,$AB29,$AC29,$AD29,$AF29,$AG29,$AH29,$Y29,AJ29)} -> 0.033999254 | AS29: {=_xll.Domino.MLModel.GetExpectedLoss(AL29,AQ29,AB29,AE29,AJ29,$M$14:$M$20,$O$14:$O$20)} -> A | AT29: 0.12 | AU29: 1139.2472 | AV29: 224.136 | AW29: 97731.686
L30: 2Y | M30: 2 | N30: 0.935569 | O30: 0.0333 | P30: 0.0051 | Q30: 0.0091 | R30: 0.014 | S30: 0.0197 | T30: 0.0368 | U30: 0.059 | X30: L017 | Y30: refi | Z30: 692 | AA30: 0.34 | AB30: 0.87 | AC30: 75 | AD30: 130000 | AE30: 117689.48 | AF30: 0.057 | AG30: 8 | AH30: 2 | AI30: 30 | AJ30: 23 | AL30: {=_xll.Domino.MLModel.GetLoanProbabilityOfDefault($Z30,$AA30,$AB30,$AC30,$AD30,$AF30,$AG30,$AH30,$Y30,1)} -> 0.015743792 | AM30: {=_xll.Domino.MLModel.GetLoanProbabilityOfDefault($Z30,$AA30,$AB30,$AC30,$AD30,$AF30,$AG30,$AH30,$Y30,2)} -> 0.031239717 | AN30: {=_xll.Domino.MLModel.GetLoanProbabilityOfDefault($Z30,$AA30,$AB30,$AC30,$AD30,$AF30,$AG30,$AH30,$Y30,5)} -> 0.076279008 | AO30: {=_xll.Domino.MLModel.GetLoanProbabilityOfDefault($Z30,$AA30,$AB30,$AC30,$AD30,$AF30,$AG30,$AH30,$Y30,10)} -> 0.14673953 | AP30: {=_xll.Domino.MLModel.GetLoanProbabilityOfDefault($Z30,$AA30,$AB30,$AC30,$AD30,$AF30,$AG30,$AH30,$Y30,30)} -> 0.37878079 | AQ30: {=_xll.Domino.MLModel.GetLoanProbabilityOfDefault($Z30,$AA30,$AB30,$AC30,$AD30,$AF30,$AG30,$AH30,$Y30,AJ30)} -> 0.30579499 | AS30: {=_xll.Domino.MLModel.GetExpectedLoss(AL30,AQ30,AB30,AE30,AJ30,$M$14:$M$20,$O$14:$O$20)} -> BB | AT30: 0.27 | AU30: 9716.9905 | AV30: 806.94962 | AW30: 58844.74
L31: 3Y | M31: 3 | N31: 0.902759 | O31: 0.0341 | P31: 0.0054 | Q31: 0.0095 | R31: 0.0146 | S31: 0.0206 | T31: 0.038 | U31: 0.0608 | X31: L018 | Y31: purchase | Z31: 706 | AA31: 0.4 | AB31: 0.89 | AC31: 56 | AD31: 410000 | AE31: 383254.61 | AF31: 0.059 | AG31: 9 | AH31: 1 | AI31: 30 | AJ31: 25 | AL31: {=_xll.Domino.MLModel.GetLoanProbabilityOfDefault($Z31,$AA31,$AB31,$AC31,$AD31,$AF31,$AG31,$AH31,$Y31,1)} -> 0.057968855 | AM31: {=_xll.Domino.MLModel.GetLoanProbabilityOfDefault($Z31,$AA31,$AB31,$AC31,$AD31,$AF31,$AG31,$AH31,$Y31,2)} -> 0.11257732 | AN31: {=_xll.Domino.MLModel.GetLoanProbabilityOfDefault($Z31,$AA31,$AB31,$AC31,$AD31,$AF31,$AG31,$AH31,$Y31,5)} -> 0.25813257 | AO31: {=_xll.Domino.MLModel.GetLoanProbabilityOfDefault($Z31,$AA31,$AB31,$AC31,$AD31,$AF31,$AG31,$AH31,$Y31,10)} -> 0.44963271 | AP31: {=_xll.Domino.MLModel.GetLoanProbabilityOfDefault($Z31,$AA31,$AB31,$AC31,$AD31,$AF31,$AG31,$AH31,$Y31,30)} -> 0.83329146 | AQ31: {=_xll.Domino.MLModel.GetLoanProbabilityOfDefault($Z31,$AA31,$AB31,$AC31,$AD31,$AF31,$AG31,$AH31,$Y31,AJ31)} -> 0.77528527 | AS31: {=_xll.Domino.MLModel.GetExpectedLoss(AL31,AQ31,AB31,AE31,AJ31,$M$14:$M$20,$O$14:$O$20)} -> B | AT31: 0.29 | AU31: 86168.18 | AV31: 2293.4356 | AW31: 191627.3
L32: 5Y | M32: 5 | N32: 0.83527 | O32: 0.036 | P32: 0.006 | Q32: 0.0103 | R32: 0.0158 | S32: 0.0224 | T32: 0.0404 | U32: 0.0644 | X32: L019 | Y32: refi | Z32: 751 | AA32: 0.24 | AB32: 0.87 | AC32: 30 | AD32: 365000 | AE32: 352182.92 | AF32: 0.055 | AG32: 2 | AH32: 0 | AI32: 30 | AJ32: 27 | AL32: {=_xll.Domino.MLModel.GetLoanProbabilityOfDefault($Z32,$AA32,$AB32,$AC32,$AD32,$AF32,$AG32,$AH32,$Y32,1)} -> 0.0034223199 | AM32: {=_xll.Domino.MLModel.GetLoanProbabilityOfDefault($Z32,$AA32,$AB32,$AC32,$AD32,$AF32,$AG32,$AH32,$Y32,2)} -> 0.0068329275 | AN32: {=_xll.Domino.MLModel.GetLoanProbabilityOfDefault($Z32,$AA32,$AB32,$AC32,$AD32,$AF32,$AG32,$AH32,$Y32,5)} -> 0.016994877 | AO32: {=_xll.Domino.MLModel.GetLoanProbabilityOfDefault($Z32,$AA32,$AB32,$AC32,$AD32,$AF32,$AG32,$AH32,$Y32,10)} -> 0.033700928 | AP32: {=_xll.Domino.MLModel.GetLoanProbabilityOfDefault($Z32,$AA32,$AB32,$AC32,$AD32,$AF32,$AG32,$AH32,$Y32,30)} -> 0.097733802 | AQ32: {=_xll.Domino.MLModel.GetLoanProbabilityOfDefault($Z32,$AA32,$AB32,$AC32,$AD32,$AF32,$AG32,$AH32,$Y32,AJ32)} -> 0.088406502 | AS32: {=_xll.Domino.MLModel.GetExpectedLoss(AL32,AQ32,AB32,AE32,AJ32,$M$14:$M$20,$O$14:$O$20)} -> BBB | AT32: 0.27 | AU32: 8406.5202 | AV32: 808.83335 | AW32: 176091.46
L33: 10Y | M33: 10 | N33: 0.666977 | O33: 0.0405 | P33: 0.0075 | Q33: 0.0123 | R33: 0.0188 | S33: 0.0269 | T33: 0.0464 | U33: 0.0734 | X33: L020 | Y33: refi | Z33: 722 | AA33: 0.32 | AB33: 0.92 | AC33: 37 | AD33: 350000 | AE33: 339616.76 | AF33: 0.077 | AG33: 1 | AH33: 0 | AI33: 30 | AJ33: 26 | AL33: {=_xll.Domino.MLModel.GetLoanProbabilityOfDefault($Z33,$AA33,$AB33,$AC33,$AD33,$AF33,$AG33,$AH33,$Y33,1)} -> 0.036765099 | AM33: {=_xll.Domino.MLModel.GetLoanProbabilityOfDefault($Z33,$AA33,$AB33,$AC33,$AD33,$AF33,$AG33,$AH33,$Y33,2)} -> 0.072178525 | AN33: {=_xll.Domino.MLModel.GetLoanProbabilityOfDefault($Z33,$AA33,$AB33,$AC33,$AD33,$AF33,$AG33,$AH33,$Y33,5)} -> 0.17079664 | AO33: {=_xll.Domino.MLModel.GetLoanProbabilityOfDefault($Z33,$AA33,$AB33,$AC33,$AD33,$AF33,$AG33,$AH33,$Y33,10)} -> 0.31242179 | AP33: {=_xll.Domino.MLModel.GetLoanProbabilityOfDefault($Z33,$AA33,$AB33,$AC33,$AD33,$AF33,$AG33,$AH33,$Y33,30)} -> 0.67493792 | AQ33: {=_xll.Domino.MLModel.GetLoanProbabilityOfDefault($Z33,$AA33,$AB33,$AC33,$AD33,$AF33,$AG33,$AH33,$Y33,AJ33)} -> 0.62239523 | AS33: {=_xll.Domino.MLModel.GetExpectedLoss(AL33,AQ33,AB33,AE33,AJ33,$M$14:$M$20,$O$14:$O$20)} -> B | AT33: 0.32 | AU33: 67640.273 | AV33: 1481.0089 | AW33: 254712.57
L34: 30Y | M34: 30 | N34: 0.274446 | O34: 0.0431 | P34: 0.0135 | Q34: 0.0203 | R34: 0.0308 | S34: 0.0449 | T34: 0.0704 | U34: 0.1094 | X34: L021 | Y34: refi | Z34: 705 | AA34: 0.17 | AB34: 0.83 | AC34: 50 | AD34: 315000 | AE34: 279306.24 | AF34: 0.068 | AG34: 7 | AH34: 0 | AI34: 20 | AJ34: 15 | AL34: {=_xll.Domino.MLModel.GetLoanProbabilityOfDefault($Z34,$AA34,$AB34,$AC34,$AD34,$AF34,$AG34,$AH34,$Y34,1)} -> 0.018256962 | AM34: {=_xll.Domino.MLModel.GetLoanProbabilityOfDefault($Z34,$AA34,$AB34,$AC34,$AD34,$AF34,$AG34,$AH34,$Y34,2)} -> 0.036180608 | AN34: {=_xll.Domino.MLModel.GetLoanProbabilityOfDefault($Z34,$AA34,$AB34,$AC34,$AD34,$AF34,$AG34,$AH34,$Y34,5)} -> 0.088011945 | AO34: {=_xll.Domino.MLModel.GetLoanProbabilityOfDefault($Z34,$AA34,$AB34,$AC34,$AD34,$AF34,$AG34,$AH34,$Y34,10)} -> 0.16827779 | AP34: {=_xll.Domino.MLModel.GetLoanProbabilityOfDefault($Z34,$AA34,$AB34,$AC34,$AD34,$AF34,$AG34,$AH34,$Y34,30)} -> 0.42464631 | AQ34: {=_xll.Domino.MLModel.GetLoanProbabilityOfDefault($Z34,$AA34,$AB34,$AC34,$AD34,$AF34,$AG34,$AH34,$Y34,AJ34)} -> 0.24147928 | AS34: {=_xll.Domino.MLModel.GetExpectedLoss(AL34,AQ34,AB34,AE34,AJ34,$M$14:$M$20,$O$14:$O$20)} -> BB | AT34: 0.23 | AU34: 15512.734 | AV34: 3590.93 | AW34: 139653.12
K35: =DATE(YEAR(K28),MONTH(K28)-1,DAY(K28)) -> 45201 | L35: {=_xll.Domino.MLModel.GetCreditCurves(K35)} -> 3M | M35: 0.25 | N35: 0.991263 | O35: 0.0351 | P35: 0.004975 | Q35: 0.0074 | R35: 0.01115 | S35: 0.018625 | T35: 0.0347 | U35: 0.05625 | X35: L022 | Y35: refi | Z35: 754 | AA35: 0.26 | AB35: 0.86 | AC35: 90 | AD35: 290000 | AE35: 253677.51 | AF35: 0.053 | AG35: 5 | AH35: 0 | AI35: 30 | AJ35: 22 | AL35: {=_xll.Domino.MLModel.GetLoanProbabilityOfDefault($Z35,$AA35,$AB35,$AC35,$AD35,$AF35,$AG35,$AH35,$Y35,1)} -> 0.0010818243 | AM35: {=_xll.Domino.MLModel.GetLoanProbabilityOfDefault($Z35,$AA35,$AB35,$AC35,$AD35,$AF35,$AG35,$AH35,$Y35,2)} -> 0.0021624783 | AN35: {=_xll.Domino.MLModel.GetLoanProbabilityOfDefault($Z35,$AA35,$AB35,$AC35,$AD35,$AF35,$AG35,$AH35,$Y35,5)} -> 0.0053974307 | AO35: {=_xll.Domino.MLModel.GetLoanProbabilityOfDefault($Z35,$AA35,$AB35,$AC35,$AD35,$AF35,$AG35,$AH35,$Y35,10)} -> 0.010765729 | AP35: {=_xll.Domino.MLModel.GetLoanProbabilityOfDefault($Z35,$AA35,$AB35,$AC35,$AD35,$AF35,$AG35,$AH35,$Y35,30)} -> 0.031950733 | AQ35: {=_xll.Domino.MLModel.GetLoanProbabilityOfDefault($Z35,$AA35,$AB35,$AC35,$AD35,$AF35,$AG35,$AH35,$Y35,AJ35)} -> 0.023531725 | AS35: {=_xll.Domino.MLModel.GetExpectedLoss(AL35,AQ35,AB35,AE35,AJ35,$M$14:$M$20,$O$14:$O$20)} -> A | AT35: 0.26 | AU35: 1552.062 | AV35: 333.02571 | AW35: 126838.76
L36: 1Y | M36: 1 | N36: 0.967248 | O36: 0.0333 | P36: 0.0052 | Q36: 0.0077 | R36: 0.0116 | S36: 0.0193 | T36: 0.0356 | U36: 0.0576 | X36: L023 | Y36: refi | Z36: 762 | AA36: 0.28 | AB36: 0.9 | AC36: 48 | AD36: 295000 | AE36: 261798.09 | AF36: 0.064 | AG36: 17 | AH36: 1 | AI36: 20 | AJ36: 16 | AL36: {=_xll.Domino.MLModel.GetLoanProbabilityOfDefault($Z36,$AA36,$AB36,$AC36,$AD36,$AF36,$AG36,$AH36,$Y36,1)} -> 0.013709784 | AM36: {=_xll.Domino.MLModel.GetLoanProbabilityOfDefault($Z36,$AA36,$AB36,$AC36,$AD36,$AF36,$AG36,$AH36,$Y36,2)} -> 0.027231609 | AN36: {=_xll.Domino.MLModel.GetLoanProbabilityOfDefault($Z36,$AA36,$AB36,$AC36,$AD36,$AF36,$AG36,$AH36,$Y36,5)} -> 0.066694929 | AO36: {=_xll.Domino.MLModel.GetLoanProbabilityOfDefault($Z36,$AA36,$AB36,$AC36,$AD36,$AF36,$AG36,$AH36,$Y36,10)} -> 0.12894164 | AP36: {=_xll.Domino.MLModel.GetLoanProbabilityOfDefault($Z36,$AA36,$AB36,$AC36,$AD36,$AF36,$AG36,$AH36,$Y36,30)} -> 0.33909087 | AQ36: {=_xll.Domino.MLModel.GetLoanProbabilityOfDefault($Z36,$AA36,$AB36,$AC36,$AD36,$AF36,$AG36,$AH36,$Y36,AJ36)} -> 0.19818237 | AS36: {=_xll.Domino.MLModel.GetExpectedLoss(AL36,AQ36,AB36,AE36,AJ36,$M$14:$M$20,$O$14:$O$20)} -> BB | AT36: 0.3 | AU36: 15565.13 | AV36: 3199.3675 | AW36: 130899.04
L37: 2Y | M37: 2 | N37: 0.935569 | O37: 0.0333 | P37: 0.0055 | Q37: 0.0081 | R37: 0.0122 | S37: 0.0202 | T37: 0.0368 | U37: 0.0594 | X37: L024 | Y37: refi | Z37: 755 | AA37: 0.22 | AB37: 0.82 | AC37: 72 | AD37: 395000 | AE37: 319832.38 | AF37: 0.058 | AG37: 1 | AH37: 0 | AI37: 20 | AJ37: 14 | AL37: {=_xll.Domino.MLModel.GetLoanProbabilityOfDefault($Z37,$AA37,$AB37,$AC37,$AD37,$AF37,$AG37,$AH37,$Y37,1)} -> 0.0063556433 | AM37: {=_xll.Domino.MLModel.GetLoanProbabilityOfDefault($Z37,$AA37,$AB37,$AC37,$AD37,$AF37,$AG37,$AH37,$Y37,2)} -> 0.012670892 | AN37: {=_xll.Domino.MLModel.GetLoanProbabilityOfDefault($Z37,$AA37,$AB37,$AC37,$AD37,$AF37,$AG37,$AH37,$Y37,5)} -> 0.031376834 | AO37: {=_xll.Domino.MLModel.GetLoanProbabilityOfDefault($Z37,$AA37,$AB37,$AC37,$AD37,$AF37,$AG37,$AH37,$Y37,10)} -> 0.061769161 | AP37: {=_xll.Domino.MLModel.GetLoanProbabilityOfDefault($Z37,$AA37,$AB37,$AC37,$AD37,$AF37,$AG37,$AH37,$Y37,30)} -> 0.17409687 | AQ37: {=_xll.Domino.MLModel.GetLoanProbabilityOfDefault($Z37,$AA37,$AB37,$AC37,$AD37,$AF37,$AG37,$AH37,$Y37,AJ37)} -> 0.085394971 | AS37: {=_xll.Domino.MLModel.GetExpectedLoss(AL37,AQ37,AB37,AE37,AJ37,$M$14:$M$20,$O$14:$O$20)} -> BB | AT37: 0.22 | AU37: 6008.6569 | AV37: 1562.2409 | AW37: 159916.19
L38: 3Y | M38: 3 | N38: 0.902759 | O38: 0.0341 | P38: 0.0058 | Q38: 0.0085 | R38: 0.0128 | S38: 0.0211 | T38: 0.038 | U38: 0.0612 | X38: L025 | Y38: refi | Z38: 756 | AA38: 0.35 | AB38: 0.84 | AC38: 49 | AD38: 255000 | AE38: 221670.97 | AF38: 0.051 | AG38: 2 | AH38: 0 | AI38: 20 | AJ38: 15 | AL38: {=_xll.Domino.MLModel.GetLoanProbabilityOfDefault($Z38,$AA38,$AB38,$AC38,$AD38,$AF38,$AG38,$AH38,$Y38,1)} -> 0.0010107756 | AM38: {=_xll.Domino.MLModel.GetLoanProbabilityOfDefault($Z38,$AA38,$AB38,$AC38,$AD38,$AF38,$AG38,$AH38,$Y38,2)} -> 0.0020205295 | AN38: {=_xll.Domino.MLModel.GetLoanProbabilityOfDefault($Z38,$AA38,$AB38,$AC38,$AD38,$AF38,$AG38,$AH38,$Y38,5)} -> 0.0050436715 | AO38: {=_xll.Domino.MLModel.GetLoanProbabilityOfDefault($Z38,$AA38,$AB38,$AC38,$AD38,$AF38,$AG38,$AH38,$Y38,10)} -> 0.010061904 | AP38: {=_xll.Domino.MLModel.GetLoanProbabilityOfDefault($Z38,$AA38,$AB38,$AC38,$AD38,$AF38,$AG38,$AH38,$Y38,30)} -> 0.029883006 | AQ38: {=_xll.Domino.MLModel.GetLoanProbabilityOfDefault($Z38,$AA38,$AB38,$AC38,$AD38,$AF38,$AG38,$AH38,$Y38,AJ38)} -> 0.015054827 | AS38: {=_xll.Domino.MLModel.GetExpectedLoss(AL38,AQ38,AB38,AE38,AJ38,$M$14:$M$20,$O$14:$O$20)} -> A | AT38: 0.24 | AU38: 800.93234 | AV38: 302.78606 | AW38: 110835.49
L39: 5Y | M39: 5 | N39: 0.83527 | O39: 0.036 | P39: 0.0064 | Q39: 0.0093 | R39: 0.014 | S39: 0.0229 | T39: 0.0404 | U39: 0.0648 | X39: L026 | Y39: refi | Z39: 792 | AA39: 0.32 | AB39: 0.91 | AC39: 51 | AD39: 310000 | AE39: 263524.38 | AF39: 0.041 | AG39: 10 | AH39: 1 | AI39: 20 | AJ39: 15 | AL39: {=_xll.Domino.MLModel.GetLoanProbabilityOfDefault($Z39,$AA39,$AB39,$AC39,$AD39,$AF39,$AG39,$AH39,$Y39,1)} -> 0.0014512539 | AM39: {=_xll.Domino.MLModel.GetLoanProbabilityOfDefault($Z39,$AA39,$AB39,$AC39,$AD39,$AF39,$AG39,$AH39,$Y39,2)} -> 0.0029004016 | AN39: {=_xll.Domino.MLModel.GetLoanProbabilityOfDefault($Z39,$AA39,$AB39,$AC39,$AD39,$AF39,$AG39,$AH39,$Y39,5)} -> 0.0072352386 | AO39: {=_xll.Domino.MLModel.GetLoanProbabilityOfDefault($Z39,$AA39,$AB39,$AC39,$AD39,$AF39,$AG39,$AH39,$Y39,10)} -> 0.014418129 | AP39: {=_xll.Domino.MLModel.GetLoanProbabilityOfDefault($Z39,$AA39,$AB39,$AC39,$AD39,$AF39,$AG39,$AH39,$Y39,30)} -> 0.042633736 | AQ39: {=_xll.Domino.MLModel.GetLoanProbabilityOfDefault($Z39,$AA39,$AB39,$AC39,$AD39,$AF39,$AG39,$AH39,$Y39,AJ39)} -> 0.021549049 | AS39: {=_xll.Domino.MLModel.GetExpectedLoss(AL39,AQ39,AB39,AE39,AJ39,$M$14:$M$20,$O$14:$O$20)} -> A | AT39: 0.31 | AU39: 1760.3969 | AV39: 665.50395 | AW39: 197643.29
L40: 10Y | M40: 10 | N40: 0.666977 | O40: 0.0405 | P40: 0.0079 | Q40: 0.0113 | R40: 0.017 | S40: 0.0274 | T40: 0.0464 | U40: 0.0738 | X40: L027 | Y40: purchase | Z40: 648 | AA40: 0.26 | AB40: 0.9 | AC40: 15 | AD40: 275000 | AE40: 271198.61 | AF40: 0.066 | AG40: 2 | AH40: 0 | AI40: 30 | AJ40: 28 | AL40: {=_xll.Domino.MLModel.GetLoanProbabilityOfDefault($Z40,$AA40,$AB40,$AC40,$AD40,$AF40,$AG40,$AH40,$Y40,1)} -> 0.024035692 | AM40: {=_xll.Domino.MLModel.GetLoanProbabilityOfDefault($Z40,$AA40,$AB40,$AC40,$AD40,$AF40,$AG40,$AH40,$Y40,2)} -> 0.04749367 | AN40: {=_xll.Domino.MLModel.GetLoanProbabilityOfDefault($Z40,$AA40,$AB40,$AC40,$AD40,$AF40,$AG40,$AH40,$Y40,5)} -> 0.11453851 | AO40: {=_xll.Domino.MLModel.GetLoanProbabilityOfDefault($Z40,$AA40,$AB40,$AC40,$AD40,$AF40,$AG40,$AH40,$Y40,10)} -> 0.21595796 | AP40: {=_xll.Domino.MLModel.GetLoanProbabilityOfDefault($Z40,$AA40,$AB40,$AC40,$AD40,$AF40,$AG40,$AH40,$Y40,30)} -> 0.51803216 | AQ40: {=_xll.Domino.MLModel.GetLoanProbabilityOfDefault($Z40,$AA40,$AB40,$AC40,$AD40,$AF40,$AG40,$AH40,$Y40,AJ40)} -> 0.49400038 | AS40: {=_xll.Domino.MLModel.GetExpectedLoss(AL40,AQ40,AB40,AE40,AJ40,$M$14:$M$20,$O$14:$O$20)} -> B | AT40: 0.3 | AU40: 40191.665 | AV40: 588.68717 | AW40: 135599.3
L41: 30Y | M41: 30 | N41: 0.274446 | O41: 0.0431 | P41: 0.0139 | Q41: 0.0193 | R41: 0.029 | S41: 0.0454 | T41: 0.0704 | U41: 0.1098 | X41: L028 | Y41: refi | Z41: 749 | AA41: 0.36 | AB41: 0.81 | AC41: 50 | AD41: 100000 | AE41: 89823.31 | AF41: 0.043 | AG41: 2 | AH41: 0 | AI41: 25 | AJ41: 20 | AL41: {=_xll.Domino.MLModel.GetLoanProbabilityOfDefault($Z41,$AA41,$AB41,$AC41,$AD41,$AF41,$AG41,$AH41,$Y41,1)} -> 0.00089979172 | AM41: {=_xll.Domino.MLModel.GetLoanProbabilityOfDefault($Z41,$AA41,$AB41,$AC41,$AD41,$AF41,$AG41,$AH41,$Y41,2)} -> 0.0017987738 | AN41: {=_xll.Domino.MLModel.GetLoanProbabilityOfDefault($Z41,$AA41,$AB41,$AC41,$AD41,$AF41,$AG41,$AH41,$Y41,5)} -> 0.0044908696 | AO41: {=_xll.Domino.MLModel.GetLoanProbabilityOfDefault($Z41,$AA41,$AB41,$AC41,$AD41,$AF41,$AG41,$AH41,$Y41,10)} -> 0.0089615713 | AP41: {=_xll.Domino.MLModel.GetLoanProbabilityOfDefault($Z41,$AA41,$AB41,$AC41,$AD41,$AF41,$AG41,$AH41,$Y41,30)} -> 0.026644504 | AQ41: {=_xll.Domino.MLModel.GetLoanProbabilityOfDefault($Z41,$AA41,$AB41,$AC41,$AD41,$AF41,$AG41,$AH41,$Y41,AJ41)} -> 0.017842833 | AS41: {=_xll.Domino.MLModel.GetExpectedLoss(AL41,AQ41,AB41,AE41,AJ41,$M$14:$M$20,$O$14:$O$20)} -> AA | AT41: 0.21 | AU41: 336.56749 | AV41: 100.56444 | AW41: 44911.655
X42: L029 | Y42: refi | Z42: 740 | AA42: 0.23 | AB42: 0.92 | AC42: 89 | AD42: 285000 | AE42: 174473.86 | AF42: 0.058 | AG42: 13 | AH42: 0 | AI42: 15 | AJ42: 7 | AL42: {=_xll.Domino.MLModel.GetLoanProbabilityOfDefault($Z42,$AA42,$AB42,$AC42,$AD42,$AF42,$AG42,$AH42,$Y42,1)} -> 0.0044608712 | AM42: {=_xll.Domino.MLModel.GetLoanProbabilityOfDefault($Z42,$AA42,$AB42,$AC42,$AD42,$AF42,$AG42,$AH42,$Y42,2)} -> 0.0089018431 | AN42: {=_xll.Domino.MLModel.GetLoanProbabilityOfDefault($Z42,$AA42,$AB42,$AC42,$AD42,$AF42,$AG42,$AH42,$Y42,5)} -> 0.022106248 | AO42: {=_xll.Domino.MLModel.GetLoanProbabilityOfDefault($Z42,$AA42,$AB42,$AC42,$AD42,$AF42,$AG42,$AH42,$Y42,10)} -> 0.04372381 | AP42: {=_xll.Domino.MLModel.GetLoanProbabilityOfDefault($Z42,$AA42,$AB42,$AC42,$AD42,$AF42,$AG42,$AH42,$Y42,30)} -> 0.12551971 | AQ42: {=_xll.Domino.MLModel.GetLoanProbabilityOfDefault($Z42,$AA42,$AB42,$AC42,$AD42,$AF42,$AG42,$AH42,$Y42,AJ42)} -> 0.030811305 | AS42: {=_xll.Domino.MLModel.GetExpectedLoss(AL42,AQ42,AB42,AE42,AJ42,$M$14:$M$20,$O$14:$O$20)} -> BBB | AT42: 0.32 | AU42: 1720.2455 | AV42: 1100.6127 | AW42: 130855.39
X43: L030 | Y43: refi | Z43: 717 | AA43: 0.18 | AB43: 0.78 | AC43: 22 | AD43: 355000 | AE43: 346186.59 | AF43: 0.08 | AG43: 2 | AH43: 0 | AI43: 25 | AJ43: 23 | AL43: {=_xll.Domino.MLModel.GetLoanProbabilityOfDefault($Z43,$AA43,$AB43,$AC43,$AD43,$AF43,$AG43,$AH43,$Y43,1)} -> 0.0092947483 | AM43: {=_xll.Domino.MLModel.GetLoanProbabilityOfDefault($Z43,$AA43,$AB43,$AC43,$AD43,$AF43,$AG43,$AH43,$Y43,2)} -> 0.018503104 | AN43: {=_xll.Domino.MLModel.GetLoanProbabilityOfDefault($Z43,$AA43,$AB43,$AC43,$AD43,$AF43,$AG43,$AH43,$Y43,5)} -> 0.045617811 | AO43: {=_xll.Domino.MLModel.GetLoanProbabilityOfDefault($Z43,$AA43,$AB43,$AC43,$AD43,$AF43,$AG43,$AH43,$Y43,10)} -> 0.089154637 | AP43: {=_xll.Domino.MLModel.GetLoanProbabilityOfDefault($Z43,$AA43,$AB43,$AC43,$AD43,$AF43,$AG43,$AH43,$Y43,30)} -> 0.24432691 | AQ43: {=_xll.Domino.MLModel.GetLoanProbabilityOfDefault($Z43,$AA43,$AB43,$AC43,$AD43,$AF43,$AG43,$AH43,$Y43,AJ43)} -> 0.19328023 | AS43: {=_xll.Domino.MLModel.GetExpectedLoss(AL43,AQ43,AB43,AE43,AJ43,$M$14:$M$20,$O$14:$O$20)} -> BB | AT43: 0.18 | AU43: 12043.984 | AV43: 1000.1953 | AW43: 121165.31
L44: =_xlfn.CONCAT("Risk Free Rate for ", TEXT(K14, "D-M-YYYY")) -> Risk Free Rate for 2-1-2024 | T44: =_xlfn.CONCAT("Credit Spreads for ", TEXT(K14, "D-M-YYYY")) -> Credit Spreads for 2-1-2024 | X44: L031 | Y44: purchase | Z44: 723 | AA44: 0.3 | AB44: 0.81 | AC44: 36 | AD44: 420000 | AE44: 404680.56 | AF44: 0.064 | AG44: 4 | AH44: 0 | AI44: 30 | AJ44: 27 | AL44: {=_xll.Domino.MLModel.GetLoanProbabilityOfDefault($Z44,$AA44,$AB44,$AC44,$AD44,$AF44,$AG44,$AH44,$Y44,1)} -> 0.026550651 | AM44: {=_xll.Domino.MLModel.GetLoanProbabilityOfDefault($Z44,$AA44,$AB44,$AC44,$AD44,$AF44,$AG44,$AH44,$Y44,2)} -> 0.052396364 | AN44: {=_xll.Domino.MLModel.GetLoanProbabilityOfDefault($Z44,$AA44,$AB44,$AC44,$AD44,$AF44,$AG44,$AH44,$Y44,5)} -> 0.12588858 | AO44: {=_xll.Domino.MLModel.GetLoanProbabilityOfDefault($Z44,$AA44,$AB44,$AC44,$AD44,$AF44,$AG44,$AH44,$Y44,10)} -> 0.23592922 | AP44: {=_xll.Domino.MLModel.GetLoanProbabilityOfDefault($Z44,$AA44,$AB44,$AC44,$AD44,$AF44,$AG44,$AH44,$Y44,30)} -> 0.5539323 | AQ44: {=_xll.Domino.MLModel.GetLoanProbabilityOfDefault($Z44,$AA44,$AB44,$AC44,$AD44,$AF44,$AG44,$AH44,$Y44,AJ44)} -> 0.5164285 | AS44: {=_xll.Domino.MLModel.GetExpectedLoss(AL44,AQ44,AB44,AE44,AJ44,$M$14:$M$20,$O$14:$O$20)} -> B | AT44: 0.21 | AU44: 43887.601 | AV44: 787.46357 | AW44: 202340.28
X45: L032 | Y45: refi | Z45: 738 | AA45: 0.38 | AB45: 0.77 | AC45: 37 | AD45: 200000 | AE45: 183167.53 | AF45: 0.064 | AG45: 4 | AH45: 0 | AI45: 20 | AJ45: 16 | AL45: {=_xll.Domino.MLModel.GetLoanProbabilityOfDefault($Z45,$AA45,$AB45,$AC45,$AD45,$AF45,$AG45,$AH45,$Y45,1)} -> 0.0058461428 | AM45: {=_xll.Domino.MLModel.GetLoanProbabilityOfDefault($Z45,$AA45,$AB45,$AC45,$AD45,$AF45,$AG45,$AH45,$Y45,2)} -> 0.011658108 | AN45: {=_xll.Domino.MLModel.GetLoanProbabilityOfDefault($Z45,$AA45,$AB45,$AC45,$AD45,$AF45,$AG45,$AH45,$Y45,5)} -> 0.028890932 | AO45: {=_xll.Domino.MLModel.GetLoanProbabilityOfDefault($Z45,$AA45,$AB45,$AC45,$AD45,$AF45,$AG45,$AH45,$Y45,10)} -> 0.056947178 | AP45: {=_xll.Domino.MLModel.GetLoanProbabilityOfDefault($Z45,$AA45,$AB45,$AC45,$AD45,$AF45,$AG45,$AH45,$Y45,30)} -> 0.16129727 | AQ45: {=_xll.Domino.MLModel.GetLoanProbabilityOfDefault($Z45,$AA45,$AB45,$AC45,$AD45,$AF45,$AG45,$AH45,$Y45,AJ45)} -> 0.089546793 | AS45: {=_xll.Domino.MLModel.GetExpectedLoss(AL45,AQ45,AB45,AE45,AJ45,$M$14:$M$20,$O$14:$O$20)} -> BB | AT45: 0.17 | AU45: 2788.351 | AV45: 573.13751 | AW45: 64108.635
X46: L033 | Y46: purchase | Z46: 769 | AA46: 0.22 | AB46: 0.85 | AC46: 60 | AD46: 175000 | AE46: 154516.24 | AF46: 0.048 | AG46: 1 | AH46: 0 | AI46: 25 | AJ46: 20 | AL46: {=_xll.Domino.MLModel.GetLoanProbabilityOfDefault($Z46,$AA46,$AB46,$AC46,$AD46,$AF46,$AG46,$AH46,$Y46,1)} -> 0.0035207868 | AM46: {=_xll.Domino.MLModel.GetLoanProbabilityOfDefault($Z46,$AA46,$AB46,$AC46,$AD46,$AF46,$AG46,$AH46,$Y46,2)} -> 0.0070291776 | AN46: {=_xll.Domino.MLModel.GetLoanProbabilityOfDefault($Z46,$AA46,$AB46,$AC46,$AD46,$AF46,$AG46,$AH46,$Y46,5)} -> 0.01748041 | AO46: {=_xll.Domino.MLModel.GetLoanProbabilityOfDefault($Z46,$AA46,$AB46,$AC46,$AD46,$AF46,$AG46,$AH46,$Y46,10)} -> 0.034655255 | AP46: {=_xll.Domino.MLModel.GetLoanProbabilityOfDefault($Z46,$AA46,$AB46,$AC46,$AD46,$AF46,$AG46,$AH46,$Y46,30)} -> 0.10040443 | AQ46: {=_xll.Domino.MLModel.GetLoanProbabilityOfDefault($Z46,$AA46,$AB46,$AC46,$AD46,$AF46,$AG46,$AH46,$Y46,AJ46)} -> 0.068109524 | AS46: {=_xll.Domino.MLModel.GetExpectedLoss(AL46,AQ46,AB46,AE46,AJ46,$M$14:$M$20,$O$14:$O$20)} -> BBB | AT46: 0.25 | AU46: 2631.0069 | AV46: 536.52969 | AW46: 77258.12
X47: L034 | Y47: refi | Z47: 689 | AA47: 0.37 | AB47: 0.92 | AC47: 19 | AD47: 355000 | AE47: 349059.63 | AF47: 0.069 | AG47: 3 | AH47: 0 | AI47: 30 | AJ47: 28 | AL47: {=_xll.Domino.MLModel.GetLoanProbabilityOfDefault($Z47,$AA47,$AB47,$AC47,$AD47,$AF47,$AG47,$AH47,$Y47,1)} -> 0.039483666 | AM47: {=_xll.Domino.MLModel.GetLoanProbabilityOfDefault($Z47,$AA47,$AB47,$AC47,$AD47,$AF47,$AG47,$AH47,$Y47,2)} -> 0.077408373 | AN47: {=_xll.Domino.MLModel.GetLoanProbabilityOfDefault($Z47,$AA47,$AB47,$AC47,$AD47,$AF47,$AG47,$AH47,$Y47,5)} -> 0.18243221 | AO47: {=_xll.Domino.MLModel.GetLoanProbabilityOfDefault($Z47,$AA47,$AB47,$AC47,$AD47,$AF47,$AG47,$AH47,$Y47,10)} -> 0.33158291 | AP47: {=_xll.Domino.MLModel.GetLoanProbabilityOfDefault($Z47,$AA47,$AB47,$AC47,$AD47,$AF47,$AG47,$AH47,$Y47,30)} -> 0.70136367 | AQ47: {=_xll.Domino.MLModel.GetLoanProbabilityOfDefault($Z47,$AA47,$AB47,$AC47,$AD47,$AF47,$AG47,$AH47,$Y47,AJ47)} -> 0.67630714 | AS47: {=_xll.Domino.MLModel.GetExpectedLoss(AL47,AQ47,AB47,AE47,AJ47,$M$14:$M$20,$O$14:$O$20)} -> B | AT47: 0.32 | AU47: 75542.886 | AV47: 1106.4764 | AW47: 261794.72
...

Sheet Spreadsheet Agent
B2: Spreadsheet agent
B3: Aren't agents just LLMs with extra steps?
B6: Layer 1 - Diagnose
B7: prompt | C7: LLM response
B8: You are a senior portfolio risk analyst. No recommendations. Diagnosis only. Given the loan inventory, decompose risk into three components: default/credit event risk, interest rate risk, and market credit spread risk. For each, state the exposure in plain terms, what move causes a loss, and how concentrated it is. Be specific to these positions, not textbook definitions. 6-9 sentences, 2-3 per factor. | C8: {=_xll.Domino.LLM.Quen(B8,'PoD Calc'!$K$10:$AW$53)} -> ### Default/Interest Rate Risk Decomposition #### Default/Interest Rate Risk Exposure: The exposure here is primarily linked to the probability of default (PD) and the associated expected loss (EL). For this loan with loan ID `L001`, the probability of default at 1 year is **0.012525200843811**. This indicates that there's a 1.25% chance that the borrower will default within one year. **What Causes a Loss?** A loss occurs when a borrower defaults, and the bank must cover the defaulted loan balance. If the loan has an outstanding balance of $302,660.57 and the bank covers the full balance upon default, the loss would be this amount. **How Concentrated is It?** The concentration of this risk is relatively moderate. With a single loan having such a high PD, a default can result in a significant financial impact on the bank, especially if many similar loans have similar characteristics. ### Market Credit Spread Risk Decomposition #### Market Credit Spread Risk Exposure: Market credit spread risk is influenced by changes in credit spreads, which affect the expected loss (EL). For `L001`, the expected loss is **$18,815.3822048809**. This figure represents the anticipated loss from the loan should it default. **What Causes a Loss?** Changes in market credit spreads directly impact the expected loss. An increase in credit spreads increases the EL because the cost of funding (represented by the risk-free rate) rises, making it more expensive to replace the defaulted loan. **How Concentrated is It?** This risk is concentrated within a single loan. While it affects a large portion of the loan’s balance, the risk is isolated to `L001`. However, if the entire portfolio has a similar structure, the impact could be broader. ### Summary For `L001`: - **Default/Interest Rate Risk:** Relatively moderate concentration due to a single loan with a high PD. - **Market Credit Spread Risk:** High exposure but concentrated within a single loan. For the entire portfolio: - **Default/Interest Rate Risk:** Requires aggregating the PDs and expected losses across all loans. - **Market Credit Spread Risk:** Requires analyzing changes in credit spreads and their impact on the entire portfolio’s expected losses.
B10: Layer 2 - Portfolio Manager Analysis
B11: Credit Default Swap Portfolio Manager | C11: LLM response | D11: Interest Rate Swap Portfolio Manager | E11: LLM response | F11: Credit Spread Hedge Portfolio Manager | G11: LLM response
B12: You are a credit derivatives specialist who structures CDS hedges for institutional loan portfolios. Given this risk decomposition, argue that CDS is the most effective hedge. Address: how CDS mitigates the identified default risk, what reference entities or indices fit the described concentration, why event-driven protection is irreplaceable here, and cost efficiency of the premium structure. Be specific to these risks. 4-5 sentences. Return responses as text, not markdown. | C12: {=_xll.Domino.LLM.Quen(B12,$C$8)} -> CDS (Credit Default Swaps) effectively mitigate both the default/interest rate risk and market credit spread risk in these scenarios. For the individual loan `L001`, the high probability of default (PD) of 1.25% necessitates a robust risk management strategy. By structuring a CDS hedge, the bank can transfer the default risk to a counterparty, ensuring that the bank only bears the residual risk. This is particularly effective given that the concentration of risk is moderate but significant, meaning that even a single default can have a substantial financial impact. For the entire portfolio, the cost efficiency of CDS premiums becomes even more critical. Since the exposure is concentrated within a few high-risk loans, the premium structure of CDS can be optimized to reflect the actual risk profile of the portfolio. Event-driven protection provided by CDS is irreplaceable here because it offers dynamic risk management capabilities, allowing the bank to adjust its risk exposure based on changes in the credit environment without having to restructure each loan individually. The premium structure ensures that the bank pays a premium only when the referenced entity defaults, thereby providing a cost-effective way to manage the overall credit risk of the portfolio. | D12: You are a rates strategist specializing in SOFR-based swap structures. Given this risk decomposition, argue that Interest Rate Swaps are the most effective hedge. Address: how a SOFR swap neutralizes the identified rate exposure, how tenor and notional map to the portfolio's duration, why the rate component is highest-priority right now, and operational simplicity versus alternatives. Be specific to these risks. 4-5 sentences. Return responses as text, not markdown. | E12: {=_xll.Domino.LLM.Quen(D12,$C$8)} -> In addressing the risks decomposed for Loan ID L001, an SOFR-based interest rate swap effectively mitigates both default/interest rate and market credit spread risks. For the default/interest rate risk, an SOFR swap can align the floating-rate portion of the loan with the SOFR index, which is less volatile than LIBOR and better reflects current market conditions. This alignment helps to reduce the variability in interest payments, thereby minimizing the risk of losses due to interest rate fluctuations. Regarding the market credit spread risk, SOFR swaps offer a hedge against changes in credit spreads by locking in a fixed interest rate, thus protecting against potential increases in the risk-free rate that could lead to higher expected losses. Additionally, the flexibility and operational simplicity of SOFR swaps make them an attractive choice over other hedges, ensuring that the portfolio's duration is well-matched to its notional value, further reducing overall risk exposure. | F12: You are a credit portfolio manager specializing in spread risk using credit index products, total return swaps, and credit spread options. Given this risk decomposition, argue that a credit spread hedge is the most effective approach. Address: how spread hedges protect without requiring a default event, how this captures day-to-day P&L volatility, why spread widening is more likely and frequent than outright default, and what index or instrument fits the sector concentration. Be specific to these risks. 4-5 sentences. Return responses as text, not markdown. | G12: {=_xll.Domino.LLM.Quen(F12,$C$8)} -> Credit spread hedges are particularly effective in protecting against the risks associated with both default and interest rate movements, especially given the nature of the risks highlighted. Unlike outright default events, which are rare and unpredictable, credit spread widening, which often reflects changes in market conditions, is more frequent and easier to anticipate. By hedging through credit spread products like credit index products, total return swaps, and credit spread options, we can capture and mitigate the volatility in market credit spreads, thereby reducing the overall risk exposure. For instance, if the loan portfolio is heavily concentrated in the technology sector, using a technology sector-specific credit spread index would be the most appropriate fit, allowing for precise risk management tailored to the unique characteristics of the portfolio.
B14: Layer 3 - Portfolio Manager Debate
B15: CDS Rebuttal | C15: LLM response | D15: IRS Rebuttal | E15: LLM response | F15: Credit Spread Rebuttal | G15: LLM response
